El bloque `try...catch` en JavaScript es una estructura de control que permite manejar errores de manera controlada. Se utiliza para envolver un bloque de código que puede lanzar excepciones, y permite capturar y manejar esas excepciones sin detener la ejecución del programa.

### Estructura Básica de `try...catch`

La estructura básica de un bloque `try...catch` es la siguiente:

```javascript
try {
  // Bloque de código que puede lanzar una excepción
} catch (error) {
  // Bloque de código para manejar el error
}
```

### Ejemplo Simple

A continuación, un ejemplo simple que muestra cómo usar `try...catch`:

```javascript
try {
  // Intentar ejecutar este código
  let resultado = 10 / 0;
  console.log("El resultado es " + resultado);
} catch (error) {
  // Capturar y manejar cualquier error que ocurra
  console.error("Ocurrió un error: " + error.message);
}

console.log("El programa continúa su ejecución.");
```

### Explicación del Ejemplo

1. **Bloque `try`**: El código dentro del bloque `try` es donde se intentará ejecutar el código que puede lanzar una excepción.
2. **Bloque `catch`**: Si ocurre una excepción en el bloque `try`, la ejecución se transfiere al bloque `catch`. La variable `error` contiene el objeto de la excepción que se lanzó.
3. **Continuación del Programa**: Después de manejar el error, el programa continúa su ejecución normal.

### Ejemplo con Funciones y Manejo de Errores

A continuación, un ejemplo más complejo que incluye una función que puede lanzar una excepción:

```javascript
function dividir(a, b) {
  if (b === 0) {
    throw new Error("División por cero no permitida");
  }
  return a / b;
}

try {
  let resultado = dividir(10, 0);
  console.log("El resultado es " + resultado);
} catch (error) {
  console.error("Ocurrió un error: " + error.message);
}

console.log("El programa continúa su ejecución.");
```

### Explicación del Ejemplo

1. **Función `dividir`**: Esta función lanza una excepción si se intenta dividir por cero.
2. **Bloque `try`**: Llama a la función `dividir` dentro del bloque `try`.
3. **Bloque `catch`**: Captura y maneja la excepción si ocurre una división por cero.

### Bloque `finally`

El bloque `finally` se puede agregar después de `try` y `catch`. El bloque `finally` se ejecuta siempre, independientemente de si ocurrió una excepción o no. Es útil para realizar cualquier limpieza o liberación de recursos necesarios.

```javascript
try {
  // Bloque de código que puede lanzar una excepción
  let resultado = dividir(10, 2);
  console.log("El resultado es " + resultado);
} catch (error) {
  // Bloque de código para manejar el error
  console.error("Ocurrió un error: " + error.message);
} finally {
  // Bloque de código que siempre se ejecuta
  console.log("Operación completada.");
}

console.log("El programa continúa su ejecución.");
```

### Uso de `finally`

1. **Limpieza de Recursos**: Liberar recursos como conexiones a bases de datos o archivos abiertos.
2. **Confirmación de Ejecución**: Confirmar que una operación ha finalizado, independientemente de su éxito o fallo.

### Resumen

El bloque `try...catch` en JavaScript es una herramienta poderosa para manejar errores de manera controlada. Permite:

- Intentar ejecutar un bloque de código que puede fallar (`try`).
- Capturar y manejar errores que ocurran en el bloque `try` (`catch`).
- Ejecutar código de limpieza o finalización independientemente del resultado (`finally`).

Esta estructura mejora la robustez y la estabilidad de tu código, permitiendo una gestión de errores más clara y controlada.
